(VAD_p396) PS C:\Users\User\Documents\repos\SHIBAL> python .\train_custom_e2e.py

=== 설정 정보 ===
데이터:
  - 훈련: custom_data/original_images_train.txt
  - 검증: custom_data/original_images_valid.txt
  - 테스트: custom_data/original_images_test.txt
  - 모델: saved_models/888tiny.pkl
훈련:
  - 모델: tiny
  - 배치 크기: 16
  - 학습률: 0.0001
  - 최대 에포크: 50
  - 드롭아웃: 0.4
GPU:
  - 멀티 GPU: True
  - GPU ID: [0, 1]
[GPU] 2개 GPU 사용: [0, 1]
  GPU 0: NVIDIA GeForce RTX 4090 (24.0GB)
  GPU 1: NVIDIA GeForce RTX 4090 (24.0GB)
[E2E] 33298개 이미지 로드됨
[E2E] 정상: 21781개, 비정상: 11517개
[E2E] 4756개 이미지 로드됨
[E2E] 정상: 3111개, 비정상: 1645개
[E2E] 9515개 이미지 로드됨
[E2E] 정상: 6224개, 비정상: 3291개
훈련 데이터: 33298개
검증 데이터: 4756개
테스트 데이터: 9515개
[OK] STEAD 모델 부분 로드: saved_models/888tiny.pkl
[GPU] DataParallel 활성화 (GPU [0, 1] 병렬)

=== End-to-End 훈련 시작 ===
Epoch 0:   0%|                                                                                                                                                                                            | 0/2082 [00:00<?, ?it/s]
전체 진행률:   0%|                                                                                                                                                                                          | 0/50 [00:00<?, ?it/s]
Traceback (most recent call last):
  File "C:\Users\User\Documents\repos\SHIBAL\train_custom_e2e.py", line 649, in <module>
    main()
  File "C:\Users\User\Documents\repos\SHIBAL\train_custom_e2e.py", line 576, in main
    train_loss = train(train_loader, model, optimizer, scheduler, device, epoch, use_multi_gpu)
  File "C:\Users\User\Documents\repos\SHIBAL\train_custom_e2e.py", line 347, in train
    bce_loss = nn.BCEWithLogitsLoss()(logits.squeeze(), labels.float())
  File "C:\Users\User\anaconda3\envs\VAD_p396\lib\site-packages\torch\nn\modules\module.py", line 1751, in _wrapped_call_impl
    return self._call_impl(*args, **kwargs)
  File "C:\Users\User\anaconda3\envs\VAD_p396\lib\site-packages\torch\nn\modules\module.py", line 1762, in _call_impl
    return forward_call(*args, **kwargs)
  File "C:\Users\User\anaconda3\envs\VAD_p396\lib\site-packages\torch\nn\modules\loss.py", line 821, in forward
    return F.binary_cross_entropy_with_logits(
  File "C:\Users\User\anaconda3\envs\VAD_p396\lib\site-packages\torch\nn\functional.py", line 3639, in binary_cross_entropy_with_logits
    raise ValueError(
ValueError: Target size (torch.Size([1, 16])) must be the same as input size (torch.Size([16]))
